[2024-02-22T18:10:04.277+0000] {taskinstance.py:1956} INFO - Dependencies all met for dep_context=non-requeueable deps ti=<TaskInstance: dibimbing_example_5.execute_sql manual__2024-02-22T18:10:01.104905+00:00 [queued]>
[2024-02-22T18:10:04.298+0000] {taskinstance.py:1956} INFO - Dependencies all met for dep_context=requeueable deps ti=<TaskInstance: dibimbing_example_5.execute_sql manual__2024-02-22T18:10:01.104905+00:00 [queued]>
[2024-02-22T18:10:04.300+0000] {taskinstance.py:2170} INFO - Starting attempt 1 of 2
[2024-02-22T18:10:04.322+0000] {taskinstance.py:2191} INFO - Executing <Task(PostgresOperator): execute_sql> on 2024-02-22 18:10:01.104905+00:00
[2024-02-22T18:10:04.341+0000] {standard_task_runner.py:60} INFO - Started process 1483 to run task
[2024-02-22T18:10:04.349+0000] {standard_task_runner.py:87} INFO - Running: ['airflow', 'tasks', 'run', 'dibimbing_example_5', 'execute_sql', 'manual__2024-02-22T18:10:01.104905+00:00', '--job-id', '59', '--raw', '--subdir', 'DAGS_FOLDER/dibimbing_example_5.py', '--cfg-path', '/tmp/tmpoiv4j7t8']
[2024-02-22T18:10:04.359+0000] {standard_task_runner.py:88} INFO - Job 59: Subtask execute_sql
[2024-02-22T18:10:04.448+0000] {task_command.py:423} INFO - Running <TaskInstance: dibimbing_example_5.execute_sql manual__2024-02-22T18:10:01.104905+00:00 [running]> on host 5c4df0f825b2
[2024-02-22T18:10:04.554+0000] {taskinstance.py:2480} INFO - Exporting env vars: AIRFLOW_CTX_DAG_OWNER='airflow' AIRFLOW_CTX_DAG_ID='dibimbing_example_5' AIRFLOW_CTX_TASK_ID='execute_sql' AIRFLOW_CTX_EXECUTION_DATE='2024-02-22T18:10:01.104905+00:00' AIRFLOW_CTX_TRY_NUMBER='1' AIRFLOW_CTX_DAG_RUN_ID='manual__2024-02-22T18:10:01.104905+00:00'
[2024-02-22T18:10:04.560+0000] {sql.py:276} INFO - Executing: SELECT * FROM my_table
[2024-02-22T18:10:04.576+0000] {base.py:83} INFO - Using connection ID 'dibimbing_***' for task execution.
[2024-02-22T18:10:04.591+0000] {base.py:83} INFO - Using connection ID 'dibimbing_***' for task execution.
[2024-02-22T18:10:04.594+0000] {taskinstance.py:2698} ERROR - Task failed with exception
Traceback (most recent call last):
  File "/home/airflow/.local/lib/python3.8/site-packages/airflow/models/taskinstance.py", line 433, in _execute_task
    result = execute_callable(context=context, **execute_callable_kwargs)
  File "/home/airflow/.local/lib/python3.8/site-packages/airflow/providers/common/sql/operators/sql.py", line 282, in execute
    output = hook.run(
  File "/home/airflow/.local/lib/python3.8/site-packages/airflow/providers/common/sql/hooks/sql.py", line 391, in run
    with closing(self.get_conn()) as conn:
  File "/home/airflow/.local/lib/python3.8/site-packages/airflow/providers/postgres/hooks/postgres.py", line 158, in get_conn
    self.conn = psycopg2.connect(**conn_args)
  File "/home/airflow/.local/lib/python3.8/site-packages/psycopg2/__init__.py", line 122, in connect
    conn = _connect(dsn, connection_factory=connection_factory, **kwasync)
psycopg2.OperationalError: connection to server on socket "/var/run/***ql/.s.PGSQL.5432" failed: No such file or directory
	Is the server running locally and accepting connections on that socket?

[2024-02-22T18:10:04.608+0000] {taskinstance.py:1138} INFO - Marking task as UP_FOR_RETRY. dag_id=dibimbing_example_5, task_id=execute_sql, execution_date=20240222T181001, start_date=20240222T181004, end_date=20240222T181004
[2024-02-22T18:10:04.621+0000] {standard_task_runner.py:107} ERROR - Failed to execute job 59 for task execute_sql (connection to server on socket "/var/run/***ql/.s.PGSQL.5432" failed: No such file or directory
	Is the server running locally and accepting connections on that socket?
; 1483)
[2024-02-22T18:10:04.660+0000] {local_task_job_runner.py:234} INFO - Task exited with return code 1
[2024-02-22T18:10:04.681+0000] {taskinstance.py:3280} INFO - 0 downstream tasks scheduled from follow-on schedule check
