[2024-02-24T06:28:52.610+0000] {taskinstance.py:1956} INFO - Dependencies all met for dep_context=non-requeueable deps ti=<TaskInstance: dibimbing_example_17.task1 manual__2024-02-24T06:28:47+00:00 [queued]>
[2024-02-24T06:28:52.620+0000] {taskinstance.py:1956} INFO - Dependencies all met for dep_context=requeueable deps ti=<TaskInstance: dibimbing_example_17.task1 manual__2024-02-24T06:28:47+00:00 [queued]>
[2024-02-24T06:28:52.623+0000] {taskinstance.py:2170} INFO - Starting attempt 1 of 2
[2024-02-24T06:28:52.639+0000] {taskinstance.py:2191} INFO - Executing <Task(PythonOperator): task1> on 2024-02-24 06:28:47+00:00
[2024-02-24T06:28:52.655+0000] {standard_task_runner.py:60} INFO - Started process 1639 to run task
[2024-02-24T06:28:52.661+0000] {standard_task_runner.py:87} INFO - Running: ['airflow', 'tasks', 'run', 'dibimbing_example_17', 'task1', 'manual__2024-02-24T06:28:47+00:00', '--job-id', '29', '--raw', '--subdir', 'DAGS_FOLDER/dibimbing_example_17.py', '--cfg-path', '/tmp/tmpmobmeces']
[2024-02-24T06:28:52.669+0000] {standard_task_runner.py:88} INFO - Job 29: Subtask task1
[2024-02-24T06:28:52.749+0000] {task_command.py:423} INFO - Running <TaskInstance: dibimbing_example_17.task1 manual__2024-02-24T06:28:47+00:00 [running]> on host 442819554f8d
[2024-02-24T06:28:52.828+0000] {taskinstance.py:2480} INFO - Exporting env vars: AIRFLOW_CTX_DAG_OWNER='dibimbing' AIRFLOW_CTX_DAG_ID='dibimbing_example_17' AIRFLOW_CTX_TASK_ID='task1' AIRFLOW_CTX_EXECUTION_DATE='2024-02-24T06:28:47+00:00' AIRFLOW_CTX_TRY_NUMBER='1' AIRFLOW_CTX_DAG_RUN_ID='manual__2024-02-24T06:28:47+00:00'
[2024-02-24T06:28:52.836+0000] {taskinstance.py:2698} ERROR - Task failed with exception
Traceback (most recent call last):
  File "/home/airflow/.local/lib/python3.8/site-packages/airflow/models/taskinstance.py", line 433, in _execute_task
    result = execute_callable(context=context, **execute_callable_kwargs)
  File "/home/airflow/.local/lib/python3.8/site-packages/airflow/operators/python.py", line 199, in execute
    return_value = self.execute_callable()
  File "/home/airflow/.local/lib/python3.8/site-packages/airflow/operators/python.py", line 216, in execute_callable
    return self.python_callable(*self.op_args, **self.op_kwargs)
  File "/opt/airflow/dags/dibimbing_example_17.py", line 25, in load_to_dwh
    df = pd.read_csv(path)
  File "/home/airflow/.local/lib/python3.8/site-packages/pandas/io/parsers/readers.py", line 912, in read_csv
    return _read(filepath_or_buffer, kwds)
  File "/home/airflow/.local/lib/python3.8/site-packages/pandas/io/parsers/readers.py", line 577, in _read
    parser = TextFileReader(filepath_or_buffer, **kwds)
  File "/home/airflow/.local/lib/python3.8/site-packages/pandas/io/parsers/readers.py", line 1407, in __init__
    self._engine = self._make_engine(f, self.engine)
  File "/home/airflow/.local/lib/python3.8/site-packages/pandas/io/parsers/readers.py", line 1661, in _make_engine
    self.handles = get_handle(
  File "/home/airflow/.local/lib/python3.8/site-packages/pandas/io/common.py", line 859, in get_handle
    handle = open(
FileNotFoundError: [Errno 2] No such file or directory: '../db/reviews_q0.csv'
[2024-02-24T06:28:52.858+0000] {taskinstance.py:1138} INFO - Marking task as UP_FOR_RETRY. dag_id=dibimbing_example_17, task_id=task1, execution_date=20240224T062847, start_date=20240224T062852, end_date=20240224T062852
[2024-02-24T06:28:52.873+0000] {standard_task_runner.py:107} ERROR - Failed to execute job 29 for task task1 ([Errno 2] No such file or directory: '../db/reviews_q0.csv'; 1639)
[2024-02-24T06:28:52.888+0000] {local_task_job_runner.py:234} INFO - Task exited with return code 1
[2024-02-24T06:28:52.909+0000] {taskinstance.py:3280} INFO - 0 downstream tasks scheduled from follow-on schedule check
