[2024-02-22T17:41:23.782+0000] {taskinstance.py:1956} INFO - Dependencies all met for dep_context=non-requeueable deps ti=<TaskInstance: dibimbing_example_5.execute_sql manual__2024-02-22T17:36:15.857023+00:00 [queued]>
[2024-02-22T17:41:23.795+0000] {taskinstance.py:1956} INFO - Dependencies all met for dep_context=requeueable deps ti=<TaskInstance: dibimbing_example_5.execute_sql manual__2024-02-22T17:36:15.857023+00:00 [queued]>
[2024-02-22T17:41:23.797+0000] {taskinstance.py:2170} INFO - Starting attempt 2 of 2
[2024-02-22T17:41:23.814+0000] {taskinstance.py:2191} INFO - Executing <Task(PostgresOperator): execute_sql> on 2024-02-22 17:36:15.857023+00:00
[2024-02-22T17:41:23.825+0000] {standard_task_runner.py:60} INFO - Started process 1060 to run task
[2024-02-22T17:41:23.830+0000] {standard_task_runner.py:87} INFO - Running: ['airflow', 'tasks', 'run', 'dibimbing_example_5', 'execute_sql', 'manual__2024-02-22T17:36:15.857023+00:00', '--job-id', '56', '--raw', '--subdir', 'DAGS_FOLDER/dibimbing_example_5.py', '--cfg-path', '/tmp/tmpu6v_n3i_']
[2024-02-22T17:41:23.834+0000] {standard_task_runner.py:88} INFO - Job 56: Subtask execute_sql
[2024-02-22T17:41:23.890+0000] {task_command.py:423} INFO - Running <TaskInstance: dibimbing_example_5.execute_sql manual__2024-02-22T17:36:15.857023+00:00 [running]> on host 5c4df0f825b2
[2024-02-22T17:41:23.963+0000] {taskinstance.py:2480} INFO - Exporting env vars: AIRFLOW_CTX_DAG_OWNER='airflow' AIRFLOW_CTX_DAG_ID='dibimbing_example_5' AIRFLOW_CTX_TASK_ID='execute_sql' AIRFLOW_CTX_EXECUTION_DATE='2024-02-22T17:36:15.857023+00:00' AIRFLOW_CTX_TRY_NUMBER='2' AIRFLOW_CTX_DAG_RUN_ID='manual__2024-02-22T17:36:15.857023+00:00'
[2024-02-22T17:41:23.966+0000] {sql.py:276} INFO - Executing: SELECT * FROM my_table
[2024-02-22T17:41:23.977+0000] {base.py:83} INFO - Using connection ID 'dibimbing_***' for task execution.
[2024-02-22T17:41:23.989+0000] {base.py:83} INFO - Using connection ID 'dibimbing_***' for task execution.
[2024-02-22T17:41:23.991+0000] {taskinstance.py:2698} ERROR - Task failed with exception
Traceback (most recent call last):
  File "/home/airflow/.local/lib/python3.8/site-packages/airflow/models/taskinstance.py", line 433, in _execute_task
    result = execute_callable(context=context, **execute_callable_kwargs)
  File "/home/airflow/.local/lib/python3.8/site-packages/airflow/providers/common/sql/operators/sql.py", line 282, in execute
    output = hook.run(
  File "/home/airflow/.local/lib/python3.8/site-packages/airflow/providers/common/sql/hooks/sql.py", line 391, in run
    with closing(self.get_conn()) as conn:
  File "/home/airflow/.local/lib/python3.8/site-packages/airflow/providers/postgres/hooks/postgres.py", line 158, in get_conn
    self.conn = psycopg2.connect(**conn_args)
  File "/home/airflow/.local/lib/python3.8/site-packages/psycopg2/__init__.py", line 122, in connect
    conn = _connect(dsn, connection_factory=connection_factory, **kwasync)
psycopg2.OperationalError: connection to server on socket "/var/run/***ql/.s.PGSQL.5432" failed: No such file or directory
	Is the server running locally and accepting connections on that socket?

[2024-02-22T17:41:24.000+0000] {taskinstance.py:1138} INFO - Marking task as FAILED. dag_id=dibimbing_example_5, task_id=execute_sql, execution_date=20240222T173615, start_date=20240222T174123, end_date=20240222T174124
[2024-02-22T17:41:24.013+0000] {standard_task_runner.py:107} ERROR - Failed to execute job 56 for task execute_sql (connection to server on socket "/var/run/***ql/.s.PGSQL.5432" failed: No such file or directory
	Is the server running locally and accepting connections on that socket?
; 1060)
[2024-02-22T17:41:24.055+0000] {local_task_job_runner.py:234} INFO - Task exited with return code 1
[2024-02-22T17:41:24.076+0000] {taskinstance.py:3280} INFO - 0 downstream tasks scheduled from follow-on schedule check
