[2024-02-22T17:33:32.085+0000] {taskinstance.py:1956} INFO - Dependencies all met for dep_context=non-requeueable deps ti=<TaskInstance: dibimbing_example_5.execute_sql manual__2024-02-22T17:33:27.281881+00:00 [queued]>
[2024-02-22T17:33:32.148+0000] {taskinstance.py:1956} INFO - Dependencies all met for dep_context=requeueable deps ti=<TaskInstance: dibimbing_example_5.execute_sql manual__2024-02-22T17:33:27.281881+00:00 [queued]>
[2024-02-22T17:33:32.161+0000] {taskinstance.py:2170} INFO - Starting attempt 1 of 2
[2024-02-22T17:33:32.241+0000] {taskinstance.py:2191} INFO - Executing <Task(PostgresOperator): execute_sql> on 2024-02-22 17:33:27.281881+00:00
[2024-02-22T17:33:32.332+0000] {standard_task_runner.py:60} INFO - Started process 942 to run task
[2024-02-22T17:33:32.351+0000] {standard_task_runner.py:87} INFO - Running: ['airflow', 'tasks', 'run', 'dibimbing_example_5', 'execute_sql', 'manual__2024-02-22T17:33:27.281881+00:00', '--job-id', '52', '--raw', '--subdir', 'DAGS_FOLDER/dibimbing_example_5.py', '--cfg-path', '/tmp/tmprf7970x9']
[2024-02-22T17:33:32.373+0000] {standard_task_runner.py:88} INFO - Job 52: Subtask execute_sql
[2024-02-22T17:33:32.606+0000] {task_command.py:423} INFO - Running <TaskInstance: dibimbing_example_5.execute_sql manual__2024-02-22T17:33:27.281881+00:00 [running]> on host 5c4df0f825b2
[2024-02-22T17:33:33.032+0000] {taskinstance.py:2480} INFO - Exporting env vars: AIRFLOW_CTX_DAG_OWNER='airflow' AIRFLOW_CTX_DAG_ID='dibimbing_example_5' AIRFLOW_CTX_TASK_ID='execute_sql' AIRFLOW_CTX_EXECUTION_DATE='2024-02-22T17:33:27.281881+00:00' AIRFLOW_CTX_TRY_NUMBER='1' AIRFLOW_CTX_DAG_RUN_ID='manual__2024-02-22T17:33:27.281881+00:00'
[2024-02-22T17:33:33.110+0000] {sql.py:276} INFO - Executing: SELECT * FROM my_table
[2024-02-22T17:33:33.279+0000] {taskinstance.py:2698} ERROR - Task failed with exception
Traceback (most recent call last):
  File "/home/airflow/.local/lib/python3.8/site-packages/airflow/models/taskinstance.py", line 433, in _execute_task
    result = execute_callable(context=context, **execute_callable_kwargs)
  File "/home/airflow/.local/lib/python3.8/site-packages/airflow/providers/common/sql/operators/sql.py", line 277, in execute
    hook = self.get_db_hook()
  File "/home/airflow/.local/lib/python3.8/site-packages/airflow/providers/common/sql/operators/sql.py", line 188, in get_db_hook
    return self._hook
  File "/usr/local/lib/python3.8/functools.py", line 967, in __get__
    val = self.func(instance)
  File "/home/airflow/.local/lib/python3.8/site-packages/airflow/providers/common/sql/operators/sql.py", line 150, in _hook
    conn = BaseHook.get_connection(conn_id)
  File "/home/airflow/.local/lib/python3.8/site-packages/airflow/hooks/base.py", line 82, in get_connection
    conn = Connection.get_connection_from_secrets(conn_id)
  File "/home/airflow/.local/lib/python3.8/site-packages/airflow/models/connection.py", line 479, in get_connection_from_secrets
    raise AirflowNotFoundException(f"The conn_id `{conn_id}` isn't defined")
airflow.exceptions.AirflowNotFoundException: The conn_id `dibimbing_***` isn't defined
[2024-02-22T17:33:33.311+0000] {taskinstance.py:1138} INFO - Marking task as UP_FOR_RETRY. dag_id=dibimbing_example_5, task_id=execute_sql, execution_date=20240222T173327, start_date=20240222T173332, end_date=20240222T173333
[2024-02-22T17:33:33.395+0000] {standard_task_runner.py:107} ERROR - Failed to execute job 52 for task execute_sql (The conn_id `dibimbing_***` isn't defined; 942)
[2024-02-22T17:33:33.540+0000] {local_task_job_runner.py:234} INFO - Task exited with return code 1
[2024-02-22T17:33:33.642+0000] {taskinstance.py:3280} INFO - 0 downstream tasks scheduled from follow-on schedule check
